 File "C:\Users\c905974\AppData\Local\Programs\Python\Python313\Lib\site-packages\urllib3\connectionpool.py", line 534, in _make_request
    response = conn.getresponse()
  File "C:\Users\c905974\AppData\Local\Programs\Python\Python313\Lib\site-packages\urllib3\connection.py", line 565, in getresponse
    httplib_response = super().getresponse()
  File "C:\Users\c905974\AppData\Local\Programs\Python\Python313\Lib\http\client.py", line 1430, in getresponse
    response.begin()
    ~~~~~~~~~~~~~~^^
  File "C:\Users\c905974\AppData\Local\Programs\Python\Python313\Lib\http\client.py", line 331, in begin
    version, status, reason = self._read_status()
                              ~~~~~~~~~~~~~~~~~^^
  File "C:\Users\c905974\AppData\Local\Programs\Python\Python313\Lib\http\client.py", line 292, in _read_status
    line = str(self.fp.readline(_MAXLINE + 1), "iso-8859-1")
               ~~~~~~~~~~~~~~~~^^^^^^^^^^^^^^
  File "C:\Users\c905974\AppData\Local\Programs\Python\Python313\Lib\socket.py", line 719, in readinto
    return self._sock.recv_into(b)
           ~~~~~~~~~~~~~~~~~~~~^^^
  File "C:\Users\c905974\AppData\Local\Programs\Python\Python313\Lib\ssl.py", line 1304, in recv_into
    return self.read(nbytes, buffer)
           ~~~~~~~~~^^^^^^^^^^^^^^^^
  File "C:\Users\c905974\AppData\Local\Programs\Python\Python313\Lib\ssl.py", line 1138, in read
    return self._sslobj.read(len, buffer)
           ~~~~~~~~~~~~~~~~~^^^^^^^^^^^^^
TimeoutError: [WinError 10060] A connection attempt failed because the connected party did not properly respond after a period of time, or established connection failed because connected host has failed to respond

The above exception was the direct cause of the following exception:

Traceback (most recent call last):
  File "C:\Users\c905974\AppData\Local\Programs\Python\Python313\Lib\site-packages\requests\adapters.py", line 644, in send
    resp = conn.urlopen(
        method=request.method,
    ...<9 lines>...
        chunked=chunked,
    )
  File "C:\Users\c905974\AppData\Local\Programs\Python\Python313\Lib\site-packages\urllib3\connectionpool.py", line 841, in urlopen
    retries = retries.increment(
        method, url, error=new_e, _pool=self, _stacktrace=sys.exc_info()[2]
    )
  File "C:\Users\c905974\AppData\Local\Programs\Python\Python313\Lib\site-packages\urllib3\util\retry.py", line 474, in increment
    raise reraise(type(error), error, _stacktrace)
          ~~~~~~~^^^^^^^^^^^^^^^^^^^^^^^^^^^^^^^^^
  File "C:\Users\c905974\AppData\Local\Programs\Python\Python313\Lib\site-packages\urllib3\util\util.py", line 39, in reraise
    raise value
  File "C:\Users\c905974\AppData\Local\Programs\Python\Python313\Lib\site-packages\urllib3\connectionpool.py", line 787, in urlopen
    response = self._make_request(
        conn,
    ...<10 lines>...
        **response_kw,
    )
  File "C:\Users\c905974\AppData\Local\Programs\Python\Python313\Lib\site-packages\urllib3\connectionpool.py", line 536, in _make_request
    self._raise_timeout(err=e, url=url, timeout_value=read_timeout)
    ~~~~~~~~~~~~~~~~~~~^^^^^^^^^^^^^^^^^^^^^^^^^^^^^^^^^^^^^^^^^^^^
  File "C:\Users\c905974\AppData\Local\Programs\Python\Python313\Lib\site-packages\urllib3\connectionpool.py", line 367, in _raise_timeout
    raise ReadTimeoutError(
        self, url, f"Read timed out. (read timeout={timeout_value})"
    ) from err
urllib3.exceptions.ReadTimeoutError: HTTPSConnectionPool(host='mytableau.cvs.com', port=443): Read timed out. (read timeout=None)

During handling of the above exception, another exception occurred:

Traceback (most recent call last):
  File "c:\Users\c905974\OneDrive - CVS Health\optimized_code_usernames.py", line 423, in <module>
    main()
    ~~~~^^
  File "c:\Users\c905974\OneDrive - CVS Health\optimized_code_usernames.py", line 320, in main
    projects_by_id, users_by_id, ds_by_id, workbooks = fetch_all_data_efficiently(server)
                                                       ~~~~~~~~~~~~~~~~~~~~~~~~~~^^^^^^^^
  File "c:\Users\c905974\OneDrive - CVS Health\optimized_code_usernames.py", line 177, in fetch_all_data_efficiently
    wb_page, w_pagination = server.workbooks.get(req_options=wb_req)
                            ~~~~~~~~~~~~~~~~~~~~^^^^^^^^^^^^^^^^^^^^
  File "C:\Users\c905974\AppData\Local\Programs\Python\Python313\Lib\site-packages\tableauserverclient\server\endpoint\endpoint.py", line 275, in wrapper    
    return func(self, *args, **kwargs)
  File "C:\Users\c905974\AppData\Local\Programs\Python\Python313\Lib\site-packages\tableauserverclient\server\endpoint\workbooks_endpoint.py", line 95, in get
    server_response = self.get_request(url, req_options)
  File "C:\Users\c905974\AppData\Local\Programs\Python\Python313\Lib\site-packages\tableauserverclient\server\endpoint\endpoint.py", line 205, in get_request
    return self._make_request(
           ~~~~~~~~~~~~~~~~~~^
        self.parent_srv.session.get,
        ^^^^^^^^^^^^^^^^^^^^^^^^^^^^
    ...<2 lines>...
        parameters=parameters,
        ^^^^^^^^^^^^^^^^^^^^^^
    )
    ^
  File "C:\Users\c905974\AppData\Local\Programs\Python\Python313\Lib\site-packages\tableauserverclient\server\endpoint\endpoint.py", line 128, in _make_request
    server_response: Optional[Union["Response", Exception]] = self.send_request_while_show_progress_threaded(
                                                              ~~~~~~~~~~~~~~~~~~~~~~~~~~~~~~~~~~~~~~~~~~~~~~^
        method, url, parameters, request_timeout
        ^^^^^^^^^^^^^^^^^^^^^^^^^^^^^^^^^^^^^^^^
    )
    ^
  File "C:\Users\c905974\AppData\Local\Programs\Python\Python313\Lib\site-packages\tableauserverclient\server\endpoint\endpoint.py", line 104, in send_request_while_show_progress_threaded
    return self._blocking_request(method, url, parameters)
           ~~~~~~~~~~~~~~~~~~~~~~^^^^^^^^^^^^^^^^^^^^^^^^^
  File "C:\Users\c905974\AppData\Local\Programs\Python\Python313\Lib\site-packages\tableauserverclient\server\endpoint\endpoint.py", line 98, in _blocking_request
    raise e
  File "C:\Users\c905974\AppData\Local\Programs\Python\Python313\Lib\site-packages\tableauserverclient\server\endpoint\endpoint.py", line 94, in _blocking_request
    response = method(url, **parameters)
  File "C:\Users\c905974\AppData\Local\Programs\Python\Python313\Lib\site-packages\requests\sessions.py", line 602, in get
    return self.request("GET", url, **kwargs)
           ~~~~~~~~~~~~^^^^^^^^^^^^^^^^^^^^^^
  File "C:\Users\c905974\AppData\Local\Programs\Python\Python313\Lib\site-packages\requests\sessions.py", line 589, in request
    resp = self.send(prep, **send_kwargs)
  File "C:\Users\c905974\AppData\Local\Programs\Python\Python313\Lib\site-packages\requests\sessions.py", line 703, in send
    r = adapter.send(request, **kwargs)
  File "C:\Users\c905974\AppData\Local\Programs\Python\Python313\Lib\site-packages\requests\adapters.py", line 690, in send
    raise ReadTimeout(e, request=request)
requests.exceptions.ReadTimeout: HTTPSConnectionPool(host='mytableau.cvs.com', port=443): Read timed out. (read timeout=None)
